[
  {
    "textPayload": "Traceback (most recent call last):\n  File \"/usr/local/lib/python3.11/site-packages/gunicorn/arbiter.py\", line 589, in spawn_worker\n    worker.init_process()\n  File \"/usr/local/lib/python3.11/site-packages/gunicorn/workers/gthread.py\", line 92, in init_process\n    super().init_process()\n  File \"/usr/local/lib/python3.11/site-packages/gunicorn/workers/base.py\", line 134, in init_process\n    self.load_wsgi()\n  File \"/usr/local/lib/python3.11/site-packages/gunicorn/workers/base.py\", line 146, in load_wsgi\n    self.wsgi = self.app.wsgi()",
    "insertId": "647588fd0007030e11f22b25",
    "resource": {
      "type": "cloud_run_revision",
      "labels": {
        "location": "us-central1",
        "service_name": "sql",
        "revision_name": "sql-00001-p2t",
        "project_id": "p003-386407",
        "configuration_name": "sql"
      }
    },
    "timestamp": "2023-05-30T05:26:21.459534Z",
    "severity": "ERROR",
    "labels": {
      "instanceId": "004d9db0be9d3893b23ef92357a5d3062153ae8ba34029357b982d355699485d83a48524d7912c0c269bdb6e3597dd11bd50765770a77bfd27f5bfa65961e3c9072c"
    },
    "logName": "projects/p003-386407/logs/run.googleapis.com%2Fstderr",
    "receiveTimestamp": "2023-05-30T05:26:21.753368798Z"
  },
  {
    "textPayload": "The request failed because either the HTTP response was malformed or connection to the instance had an error. Additional troubleshooting documentation can be found at: https://cloud.google.com/run/docs/troubleshooting#malformed-response-or-connection-error",
    "insertId": "647588fd00080951da7a0440",
    "httpRequest": {
      "requestMethod": "GET",
      "requestUrl": "https://sql-mwt7cqbx4a-uc.a.run.app/favicon.ico",
      "requestSize": "1045",
      "status": 503,
      "responseSize": "954",
      "userAgent": "Mozilla/5.0 (Macintosh; Intel Mac OS X 10_15_7) AppleWebKit/537.36 (KHTML, like Gecko) Chrome/114.0.0.0 Safari/537.36",
      "remoteIp": "111.98.70.1",
      "referer": "https://sql-mwt7cqbx4a-uc.a.run.app/",
      "serverIp": "216.239.36.53",
      "latency": "0.697729555s",
      "protocol": "HTTP/1.1"
    },
    "resource": {
      "type": "cloud_run_revision",
      "labels": {
        "configuration_name": "sql",
        "revision_name": "sql-00001-p2t",
        "location": "us-central1",
        "project_id": "p003-386407",
        "service_name": "sql"
      }
    },
    "timestamp": "2023-05-30T05:26:20.772997Z",
    "severity": "ERROR",
    "labels": {
      "instanceId": "004d9db0be9d3893b23ef92357a5d3062153ae8ba34029357b982d355699485d83a48524d7912c0c269bdb6e3597dd11bd50765770a77bfd27f5bfa65961e3c9072c"
    },
    "logName": "projects/p003-386407/logs/run.googleapis.com%2Frequests",
    "trace": "projects/p003-386407/traces/a2ba4cfeba8a1c8e8b930a2b82409dd6",
    "receiveTimestamp": "2023-05-30T05:26:21.591291006Z",
    "spanId": "15962229814527852603"
  },
  {
    "textPayload": "Traceback (most recent call last):\n  File \"/usr/local/lib/python3.11/site-packages/gunicorn/arbiter.py\", line 589, in spawn_worker\n    worker.init_process()\n  File \"/usr/local/lib/python3.11/site-packages/gunicorn/workers/gthread.py\", line 92, in init_process\n    super().init_process()\n  File \"/usr/local/lib/python3.11/site-packages/gunicorn/workers/base.py\", line 134, in init_process\n    self.load_wsgi()\n  File \"/usr/local/lib/python3.11/site-packages/gunicorn/workers/base.py\", line 146, in load_wsgi\n    self.wsgi = self.app.wsgi()",
    "insertId": "647588fc0007240fef1746fd",
    "resource": {
      "type": "cloud_run_revision",
      "labels": {
        "location": "us-central1",
        "configuration_name": "sql",
        "project_id": "p003-386407",
        "revision_name": "sql-00001-p2t",
        "service_name": "sql"
      }
    },
    "timestamp": "2023-05-30T05:26:20.467983Z",
    "severity": "ERROR",
    "labels": {
      "instanceId": "004d9db0be0466c6cb6032071f20733bfbe89af02c3e16dedd81f03cff29fd4a3c3763c7f5aa7b6a1facd162cf8a908c81fd35805ce4e05d7dce9d3f6fee6ec5b050"
    },
    "logName": "projects/p003-386407/logs/run.googleapis.com%2Fstderr",
    "receiveTimestamp": "2023-05-30T05:26:20.755877381Z"
  },
  {
    "textPayload": "The request failed because either the HTTP response was malformed or connection to the instance had an error. Additional troubleshooting documentation can be found at: https://cloud.google.com/run/docs/troubleshooting#malformed-response-or-connection-error",
    "insertId": "647588fc0008f4c8d982380d",
    "httpRequest": {
      "requestMethod": "GET",
      "requestUrl": "https://sql-mwt7cqbx4a-uc.a.run.app/",
      "requestSize": "1155",
      "status": 503,
      "responseSize": "954",
      "userAgent": "Mozilla/5.0 (Macintosh; Intel Mac OS X 10_15_7) AppleWebKit/537.36 (KHTML, like Gecko) Chrome/114.0.0.0 Safari/537.36",
      "remoteIp": "111.98.70.1",
      "referer": "https://console.cloud.google.com/",
      "serverIp": "216.239.36.53",
      "latency": "1.114547546s",
      "protocol": "HTTP/1.1"
    },
    "resource": {
      "type": "cloud_run_revision",
      "labels": {
        "service_name": "sql",
        "project_id": "p003-386407",
        "configuration_name": "sql",
        "location": "us-central1",
        "revision_name": "sql-00001-p2t"
      }
    },
    "timestamp": "2023-05-30T05:26:19.305459Z",
    "severity": "ERROR",
    "labels": {
      "instanceId": "004d9db0be0466c6cb6032071f20733bfbe89af02c3e16dedd81f03cff29fd4a3c3763c7f5aa7b6a1facd162cf8a908c81fd35805ce4e05d7dce9d3f6fee6ec5b050"
    },
    "logName": "projects/p003-386407/logs/run.googleapis.com%2Frequests",
    "trace": "projects/p003-386407/traces/8fc72fbb7cdf04ea37062605c0f84979",
    "receiveTimestamp": "2023-05-30T05:26:20.591946358Z",
    "spanId": "110257454236754013",
    "traceSampled": true
  },
  {
    "textPayload": "Traceback (most recent call last):\n  File \"/usr/local/lib/python3.11/site-packages/gunicorn/arbiter.py\", line 589, in spawn_worker\n    worker.init_process()\n  File \"/usr/local/lib/python3.11/site-packages/gunicorn/workers/gthread.py\", line 92, in init_process\n    super().init_process()\n  File \"/usr/local/lib/python3.11/site-packages/gunicorn/workers/base.py\", line 134, in init_process\n    self.load_wsgi()\n  File \"/usr/local/lib/python3.11/site-packages/gunicorn/workers/base.py\", line 146, in load_wsgi\n    self.wsgi = self.app.wsgi()",
    "insertId": "647588f200082c8eb19827eb",
    "resource": {
      "type": "cloud_run_revision",
      "labels": {
        "service_name": "sql",
        "configuration_name": "sql",
        "location": "us-central1",
        "project_id": "p003-386407",
        "revision_name": "sql-00001-p2t"
      }
    },
    "timestamp": "2023-05-30T05:26:10.535694Z",
    "severity": "ERROR",
    "labels": {
      "instanceId": "004d9db0be80c8ebcce339c4cd65969a154733146c7bbf0c7390e79a06318981b791dc6e41057af14c188d8e83cd4dc62aa9779e4dd00d803bdcabbc8045ff9830"
    },
    "logName": "projects/p003-386407/logs/run.googleapis.com%2Fstderr",
    "receiveTimestamp": "2023-05-30T05:26:10.827898838Z"
  }
]